## SLURM PROLOG ###############################################################
##    Job ID : 11193522
##  Job Name : danq_training
##  Nodelist : gpu2004
##      CPUs : 1
##  Mem/Node : 65536 MB
## Directory : /oscar/home/jyphan/danq_project
##   Job Started : Mon Apr 28 03:08:58 PM EDT 2025
###############################################################################
loading model
Starting training
Traceback (most recent call last):
  File "/oscar/home/jyphan/danq_project/./main.py", line 166, in <module>
    model = train(model, train_loader, val_loader, device, num_epochs=30, patience=3)
  File "/oscar/home/jyphan/danq_project/./main.py", line 36, in train
    for sequences, targets in train_loader:
  File "/users/jyphan/.conda/envs/danq_env/lib/python3.9/site-packages/torch/utils/data/dataloader.py", line 708, in __next__
    data = self._next_data()
  File "/users/jyphan/.conda/envs/danq_env/lib/python3.9/site-packages/torch/utils/data/dataloader.py", line 1480, in _next_data
    return self._process_data(data)
  File "/users/jyphan/.conda/envs/danq_env/lib/python3.9/site-packages/torch/utils/data/dataloader.py", line 1505, in _process_data
    data.reraise()
  File "/users/jyphan/.conda/envs/danq_env/lib/python3.9/site-packages/torch/_utils.py", line 733, in reraise
    raise exception
KeyError: Caught KeyError in DataLoader worker process 0.
Original Traceback (most recent call last):
  File "/users/jyphan/.conda/envs/danq_env/lib/python3.9/site-packages/pandas/core/indexes/base.py", line 3805, in get_loc
    return self._engine.get_loc(casted_key)
  File "index.pyx", line 167, in pandas._libs.index.IndexEngine.get_loc
  File "index.pyx", line 196, in pandas._libs.index.IndexEngine.get_loc
  File "pandas/_libs/hashtable_class_helper.pxi", line 7081, in pandas._libs.hashtable.PyObjectHashTable.get_item
  File "pandas/_libs/hashtable_class_helper.pxi", line 7089, in pandas._libs.hashtable.PyObjectHashTable.get_item
KeyError: 'sequence'

The above exception was the direct cause of the following exception:

Traceback (most recent call last):
  File "/users/jyphan/.conda/envs/danq_env/lib/python3.9/site-packages/torch/utils/data/_utils/worker.py", line 349, in _worker_loop
    data = fetcher.fetch(index)  # type: ignore[possibly-undefined]
  File "/users/jyphan/.conda/envs/danq_env/lib/python3.9/site-packages/torch/utils/data/_utils/fetch.py", line 50, in fetch
    data = self.dataset.__getitems__(possibly_batched_index)
  File "/users/jyphan/.conda/envs/danq_env/lib/python3.9/site-packages/torch/utils/data/dataset.py", line 420, in __getitems__
    return [self.dataset[self.indices[idx]] for idx in indices]
  File "/users/jyphan/.conda/envs/danq_env/lib/python3.9/site-packages/torch/utils/data/dataset.py", line 420, in <listcomp>
    return [self.dataset[self.indices[idx]] for idx in indices]
  File "/oscar/home/jyphan/danq_project/preprocessing/sequence_dataset.py", line 25, in __getitem__
    seq = self.data.iloc[idx]["sequence"]
  File "/users/jyphan/.conda/envs/danq_env/lib/python3.9/site-packages/pandas/core/series.py", line 1121, in __getitem__
    return self._get_value(key)
  File "/users/jyphan/.conda/envs/danq_env/lib/python3.9/site-packages/pandas/core/series.py", line 1237, in _get_value
    loc = self.index.get_loc(label)
  File "/users/jyphan/.conda/envs/danq_env/lib/python3.9/site-packages/pandas/core/indexes/base.py", line 3812, in get_loc
    raise KeyError(key) from err
KeyError: 'sequence'

